<?xml version="1.0" encoding="utf-8"?>
<!-- =================================================================================== -->
<!-- |    This document was autogenerated by xacro from panda_arm.urdf.xacro           | -->
<!-- |    EDITING THIS FILE BY HAND IS NOT RECOMMENDED                                 | -->
<!-- =================================================================================== -->
<robot name="panda">
  <link name="world"/>
  <link name="base_link"/>
  <material name="light_gray">
    <color rgba="0.7 0.7 0.7 1"/>
  </material>
  <material name="red">
    <color rgba="1.0 0.1 0.1 1"/>
  </material>
  <link name="workcell_base">
    <visual>
      <geometry>
        <mesh filename="package://pick_and_place_support/meshes/workcell.STL"/>
      </geometry>
      <material name="light_gray"/>
    </visual>
    <collision name="workcell_table">
      <geometry>
        <box size="0.8 1.25 0.77153"/>
      </geometry>
      <origin xyz="0.0 0.3 -0.385765"/>
    </collision>
    <collision name="workcell_columnSW">
      <geometry>
        <box size="0.1 0.1 1.25"/>
      </geometry>
      <origin xyz="-.3302 -.2794 0.6"/>
    </collision>
    <collision name="workcell_columnsSE">
      <geometry>
        <box size="0.1 0.1 1.25"/>
      </geometry>
      <origin xyz=".3302 -.2794 0.6"/>
    </collision>
    <collision name="workcell_columnNW">
      <geometry>
        <box size="0.1 0.1 1.25"/>
      </geometry>
      <origin xyz="-.3302 0.8382 0.6"/>
      colors
    
    </collision>
    <collision name="workcell_columnNE">
      <geometry>
        <box size="0.1 0.1 1.25"/>
      </geometry>
      <origin xyz=".3302 0.8382 0.6"/>
    </collision>
    <collision name="workcell_top">
      <geometry>
        <box size="0.95 1.4 0.2"/>
      </geometry>
      <origin xyz="0.0 0.3 1.2"/>
    </collision>
  </link>
  <joint name="workcell_joint" type="fixed">
    <origin rpy="0 0 0" xyz="0.0 0.0 0.77153"/>
    <parent link="world"/>
    <child link="workcell_base"/>
  </joint>
  <link name="cabinet_1">
    <collision name="cabinet_1_back">
      <geometry>
        <box size="0.5969 0.0254 0.762"/>
      </geometry>
      <origin xyz=".2985 -.0127 -0.381"/>
    </collision>
    <collision name="cabinet_1_sideL">
      <geometry>
        <box size="0.0254 0.3048 0.762"/>
      </geometry>
      <origin xyz="0.0127 -0.1524 -0.381"/>
    </collision>
    <collision name="cabinet_1_sideR">
      <geometry>
        <box size="0.0254 0.3048 0.762"/>
      </geometry>
      <origin xyz="0.5969 -0.1524 -0.381"/>
    </collision>
    <collision name="cabinet_1_cabinet1">
      <geometry>
        <box size="0.5969 0.3048 0.0254"/>
      </geometry>
      <origin xyz=".2985 -0.1524  -0.7493"/>
    </collision>
    <collision name="cabinet_1_cabinet2">
      <geometry>
        <box size="0.5969 0.3048 0.0254"/>
      </geometry>
      <origin xyz=".2985 -0.1524  -0.508"/>
    </collision>
    <collision name="cabinet_1_cabinet3">
      <geometry>
        <box size="0.5969 0.3048 0.0254"/>
      </geometry>
      <origin xyz=".2985 -0.1524  -0.254"/>
    </collision>
    <collision name="cabinet_1_cabinet4">
      <geometry>
        <box size="0.5969 0.3048 0.0254"/>
      </geometry>
      <origin xyz=".2985 -0.1524  -0.0127"/>
    </collision>
  </link>
  <joint name="cabinet_1_joint" type="fixed">
    <origin rpy="0 0 0" xyz="-0.3048 1.016 0.771525"/>
    <parent link="workcell_base"/>
    <child link="cabinet_1"/>
  </joint>
  <!-- Create joints -->
  <joint name="workcell_base_to_base" type="fixed">
    <parent link="workcell_base"/>
    <child link="base_link"/>
    <origin rpy="0 0 1.5708" xyz="0 -0.0381 0.00953"/>
  </joint>
  <joint name="panda_joint_base_link" type="fixed">
    <parent link="base_link"/>
    <child link="panda_link0"/>
    <origin rpy="0 0 0" xyz="0 0 0"/>
  </joint>
  <link name="panda_link0">
    <visual>
      <geometry>
        <mesh filename="package://franka_description/meshes/visual/link0.dae"/>
      </geometry>
    </visual>
    <collision>
      <origin rpy="0 1.57079632679 0" xyz="-0.075 0 0.06"/>
      <geometry>
        <cylinder length="0.03" radius="0.07"/>
      </geometry>
    </collision>
    <collision>
      <origin rpy="0 0 0" xyz="-0.06 0 0.06"/>
      <geometry>
        <sphere radius="0.07"/>
      </geometry>
    </collision>
    <collision>
      <origin rpy="0 0 0" xyz="-0.09 0 0.06"/>
      <geometry>
        <sphere radius="0.07"/>
      </geometry>
    </collision>
  </link>
  <link name="panda_link1">
    <visual>
      <geometry>
        <mesh filename="package://franka_description/meshes/visual/link1.dae"/>
      </geometry>
    </visual>
    <collision>
      <origin rpy="0 0 0" xyz="0 0 -0.1915"/>
      <geometry>
        <cylinder length="0.2830" radius="0.07"/>
      </geometry>
    </collision>
    <collision>
      <origin rpy="0 0 0" xyz="0 0 -0.05"/>
      <geometry>
        <sphere radius="0.07"/>
      </geometry>
    </collision>
  </link>
  <joint name="panda_joint1" type="revolute">
    <safety_controller k_position="100.0" k_velocity="40.0" soft_lower_limit="-2.8973" soft_upper_limit="2.8973"/>
    <origin rpy="0 0 0" xyz="0 0 0.333"/>
    <parent link="panda_link0"/>
    <child link="panda_link1"/>
    <axis xyz="0 0 1"/>
    <limit effort="87" lower="-2.8973" upper="2.8973" velocity="2.1750"/>
  </joint>
  <link name="panda_link2">
    <visual>
      <geometry>
        <mesh filename="package://franka_description/meshes/visual/link2.dae"/>
      </geometry>
    </visual>
    <collision>
      <origin rpy="0 0 0" xyz="0 0 0"/>
      <geometry>
        <cylinder length="0.12" radius="0.07"/>
      </geometry>
    </collision>
    <collision>
      <origin rpy="0 0 0" xyz="0 0 -0.06"/>
      <geometry>
        <sphere radius="0.07"/>
      </geometry>
    </collision>
    <collision>
      <origin rpy="0 0 0" xyz="0 0 0.06"/>
      <geometry>
        <sphere radius="0.07"/>
      </geometry>
    </collision>
  </link>
  <joint name="panda_joint2" type="revolute">
    <safety_controller k_position="100.0" k_velocity="40.0" soft_lower_limit="-1.7628" soft_upper_limit="1.7628"/>
    <origin rpy="-1.57079632679 0 0" xyz="0 0 0"/>
    <parent link="panda_link1"/>
    <child link="panda_link2"/>
    <axis xyz="0 0 1"/>
    <limit effort="87" lower="-1.7628" upper="1.7628" velocity="2.1750"/>
  </joint>
  <link name="panda_link3">
    <visual>
      <geometry>
        <mesh filename="package://franka_description/meshes/visual/link3.dae"/>
      </geometry>
    </visual>
    <collision>
      <origin rpy="0 0 0" xyz="0 0 -0.145"/>
      <geometry>
        <cylinder length="0.15" radius="0.07"/>
      </geometry>
    </collision>
    <collision>
      <origin rpy="0 0 0" xyz="0 0 -0.22"/>
      <geometry>
        <sphere radius="0.07"/>
      </geometry>
    </collision>
    <collision>
      <origin rpy="0 0 0" xyz="0 0 -0.07"/>
      <geometry>
        <sphere radius="0.07"/>
      </geometry>
    </collision>
  </link>
  <joint name="panda_joint3" type="revolute">
    <safety_controller k_position="100.0" k_velocity="40.0" soft_lower_limit="-2.8973" soft_upper_limit="2.8973"/>
    <origin rpy="1.57079632679 0 0" xyz="0 -0.316 0"/>
    <parent link="panda_link2"/>
    <child link="panda_link3"/>
    <axis xyz="0 0 1"/>
    <limit effort="87" lower="-2.8973" upper="2.8973" velocity="2.1750"/>
  </joint>
  <link name="panda_link4">
    <visual>
      <geometry>
        <mesh filename="package://franka_description/meshes/visual/link4.dae"/>
      </geometry>
    </visual>
    <collision>
      <origin rpy="0 0 0" xyz="0 0 0"/>
      <geometry>
        <cylinder length="0.12" radius="0.07"/>
      </geometry>
    </collision>
    <collision>
      <origin rpy="0 0 0" xyz="0 0 0.06"/>
      <geometry>
        <sphere radius="0.07"/>
      </geometry>
    </collision>
    <collision>
      <origin rpy="0 0 0" xyz="0 0 -0.06"/>
      <geometry>
        <sphere radius="0.07"/>
      </geometry>
    </collision>
  </link>
  <joint name="panda_joint4" type="revolute">
    <safety_controller k_position="100.0" k_velocity="40.0" soft_lower_limit="-3.0718" soft_upper_limit="-0.0698"/>
    <origin rpy="1.57079632679 0 0" xyz="0.0825 0 0"/>
    <parent link="panda_link3"/>
    <child link="panda_link4"/>
    <axis xyz="0 0 1"/>
    <limit effort="87" lower="-3.0718" upper="-0.0698" velocity="2.1750"/>
  </joint>
  <link name="panda_link5">
    <visual>
      <geometry>
        <mesh filename="package://franka_description/meshes/visual/link5.dae"/>
      </geometry>
    </visual>
    <collision>
      <origin rpy="0 0 0" xyz="0 0 -0.26"/>
      <geometry>
        <cylinder length="0.1" radius="0.07"/>
      </geometry>
    </collision>
    <collision>
      <origin rpy="0 0 0" xyz="0 0 -0.31"/>
      <geometry>
        <sphere radius="0.07"/>
      </geometry>
    </collision>
    <collision>
      <origin rpy="0 0 0" xyz="0 0 -0.21"/>
      <geometry>
        <sphere radius="0.07"/>
      </geometry>
    </collision>
    <collision>
      <origin rpy="0 0 0" xyz="0 0.08 -0.13"/>
      <geometry>
        <cylinder length="0.14" radius="0.035"/>
      </geometry>
    </collision>
    <collision>
      <origin rpy="0 0 0" xyz="0 0.08 -0.06"/>
      <geometry>
        <sphere radius="0.035"/>
      </geometry>
    </collision>
    <collision>
      <origin rpy="0 0 0" xyz="0 0.08 -0.20"/>
      <geometry>
        <sphere radius="0.035"/>
      </geometry>
    </collision>
  </link>
  <joint name="panda_joint5" type="revolute">
    <safety_controller k_position="100.0" k_velocity="40.0" soft_lower_limit="-2.8973" soft_upper_limit="2.8973"/>
    <origin rpy="-1.57079632679 0 0" xyz="-0.0825 0.384 0"/>
    <parent link="panda_link4"/>
    <child link="panda_link5"/>
    <axis xyz="0 0 1"/>
    <limit effort="12" lower="-2.8973" upper="2.8973" velocity="2.6100"/>
  </joint>
  <link name="panda_link6">
    <visual>
      <geometry>
        <mesh filename="package://franka_description/meshes/visual/link6.dae"/>
      </geometry>
    </visual>
    <collision>
      <origin rpy="0 0 0" xyz="0 0 -0.03"/>
      <geometry>
        <cylinder length="0.08" radius="0.06"/>
      </geometry>
    </collision>
    <collision>
      <origin rpy="0 0 0" xyz="0 0 0.01"/>
      <geometry>
        <sphere radius="0.06"/>
      </geometry>
    </collision>
    <collision>
      <origin rpy="0 0 0" xyz="0 0 -0.07"/>
      <geometry>
        <sphere radius="0.06"/>
      </geometry>
    </collision>
  </link>
  <joint name="panda_joint6" type="revolute">
    <safety_controller k_position="100.0" k_velocity="40.0" soft_lower_limit="-0.0175" soft_upper_limit="3.7525"/>
    <origin rpy="1.57079632679 0 0" xyz="0 0 0"/>
    <parent link="panda_link5"/>
    <child link="panda_link6"/>
    <axis xyz="0 0 1"/>
    <limit effort="12" lower="-0.0175" upper="3.7525" velocity="2.6100"/>
  </joint>
  <link name="panda_link7">
    <visual>
      <geometry>
        <mesh filename="package://franka_description/meshes/visual/link7.dae"/>
      </geometry>
    </visual>
    <collision>
      <origin rpy="0 0 0" xyz="0 0 0.01"/>
      <geometry>
        <cylinder length="0.14" radius="0.05"/>
      </geometry>
    </collision>
    <collision>
      <origin rpy="0 0 0" xyz="0 0 0.08"/>
      <geometry>
        <sphere radius="0.05"/>
      </geometry>
    </collision>
    <collision>
      <origin rpy="0 0 0" xyz="0 0 -0.06"/>
      <geometry>
        <sphere radius="0.05"/>
      </geometry>
    </collision>
  </link>
  <joint name="panda_joint7" type="revolute">
    <safety_controller k_position="100.0" k_velocity="40.0" soft_lower_limit="-2.8973" soft_upper_limit="2.8973"/>
    <origin rpy="1.57079632679 0 0" xyz="0.088 0 0"/>
    <parent link="panda_link6"/>
    <child link="panda_link7"/>
    <axis xyz="0 0 1"/>
    <limit effort="12" lower="-2.8973" upper="2.8973" velocity="2.6100"/>
  </joint>
  <link name="panda_link8">
    <collision>
      <origin rpy="3.14159265359 1.57079632679 1.57079632679" xyz="0.0424 0.0424 -0.0250"/>
      <geometry>
        <cylinder length="0.01" radius="0.04"/>
      </geometry>
    </collision>
    <collision>
      <origin rpy="0 0 0" xyz="0.0424 0.0424 -0.02"/>
      <geometry>
        <sphere radius="0.04"/>
      </geometry>
    </collision>
    <collision>
      <origin rpy="0 0 0" xyz="0.0424 0.0424 -0.03"/>
      <geometry>
        <sphere radius="0.04"/>
      </geometry>
    </collision>
  </link>
  <joint name="panda_joint8" type="fixed">
    <origin rpy="0 0 0" xyz="0 0 0.107"/>
    <parent link="panda_link7"/>
    <child link="panda_link8"/>
  </joint>
  <joint name="panda_suction_ee_joint" type="fixed">
    <parent link="panda_link8"/>
    <child link="panda_suction_ee"/>
    <origin rpy="0 0 0" xyz="0 0 0"/>
  </joint>
  <link name="panda_suction_ee">
    <visual>
      <origin rpy="1.57079632679 0 0" xyz="-0.03429 0.03429 0"/>
      <geometry>
        <mesh filename="package://pick_and_place_support/include/robot_description/suction_ee.stl"/>
      </geometry>
    </visual>
    <collision>
      <origin rpy="0 0 0" xyz="0 0 0.045577"/>
      <geometry>
        <cylinder length="0.091154" radius="0.03429"/>
      </geometry>
    </collision>
  </link>
  <!-- Define the hand_tcp frame. This is a virtual  -->
  <link name="panda_ee_tcp"/>
  <joint name="panda_hand_tcp_joint" type="fixed">
    <origin rpy="0 0 0" xyz="0 0 0.091154"/>
    <parent link="panda_suction_ee"/>
    <child link="panda_ee_tcp"/>
  </joint>
  <joint name="case_cam_joint" type="fixed">
    <parent link="panda_link0"/>
    <child link="case_cam"/>
    <origin rpy="0.375 0 0" xyz="0.1637786 -0.5589 0.736"/>
  </joint>
  <link name="case_cam">
    <visual>
      <origin rpy="0 3.14159265359 0" xyz="0 0 0"/>
      <geometry>
        <mesh filename="package://pick_and_place_support/include/robot_description/oak-d-camera.stl"/>
      </geometry>
    </visual>
    <collision>
      <origin rpy="0 0 0" xyz="0 0 0"/>
      <geometry>
        <sphere radius="0.03429"/>
      </geometry>
    </collision>
  </link>
  <joint name="fine_shelf_cam_joint" type="fixed">
    <parent link="panda_link0"/>
    <child link="fine_shelf_cam"/>
    <origin rpy="1.57079632679 0 0" xyz=".2189801 -0.04 0.127"/>
  </joint>
  <link name="fine_shelf_cam">
    <visual>
      <origin rpy="0 3.14159265359 0" xyz="0 0 0"/>
      <geometry>
        <mesh filename="package://pick_and_place_support/include/robot_description/oak-d-camera.stl"/>
      </geometry>
    </visual>
    <collision>
      <origin rpy="0 0 0" xyz="0 0 0"/>
      <geometry>
        <sphere radius="0.03429"/>
      </geometry>
    </collision>
  </link>
  <!--<xacro:include filename="$(find pick_and_place_support)/config/panda_arm.ros2_control.xacro"/>
  <xacro:panda_arm_ros2_control ns="$(arg arm_id)" robot_ip="$(arg robot_ip)" use_fake_hardware="$(arg use_fake_hardware)" fake_sensor_commands="$(arg fake_sensor_commands)"/> -->
</robot>

